<?xml version="1.0"?>
<robot name="pydantic_robot">

  <link name="base">
    <inertial>
      <origin xyz="0 0 0" rpy="0 0 0"/>
      <mass value="0.5"/>
      <inertia ixx="0.00043333333333333337" ixy="0" ixz="0"
               iyy="0.00043333333333333337" iyz="0"
               izz="0.0008333333333333335"/>
    </inertial>
    <visual>
      <origin xyz="0 0 0" rpy="0 0 0"/>
      <geometry>
        <box size="0.1 0.1 0.02"/>
      </geometry>
    </visual>
    <collision>
      <origin xyz="0 0 0" rpy="0 0 0"/>
      <geometry>
        <box size="0.1 0.1 0.02"/>
      </geometry>
    </collision>
  </link>



  <link name="f1_s1">
    <inertial>
      <origin xyz="0 0 0.025" rpy="0 0 0"/>
      <mass value="0.05"/>
      <inertia ixx="1.1666666666666668e-05" iyy="1.1666666666666668e-05" izz="2.5e-06" ixy="0" ixz="0" iyz="0"/>
    </inertial>
    <visual>
      <origin xyz="0 0 0.025" rpy="0 0 0"/>
      <geometry>
        <cylinder radius="0.01" length="0.05"/>
      </geometry>
    </visual>
    <collision>
      <origin xyz="0 0 0.025" rpy="0 0 0"/>
      <geometry>
        <cylinder radius="0.01" length="0.05"/>
      </geometry>
    </collision>
  </link>

  <joint name="j_base_to_f1_s1" type="revolute">
    <parent link="base"/>
    <child link="f1_s1"/>
    <origin 
      xyz="0.05 0.0 0.0" 
      rpy="0 0 3.1415"
    />
    <axis xyz="0 1 0"/>
    <limit 
      lower="-0.7" 
      upper="1.57" 
      effort="10" velocity="1.0"
    />
    <dynamics damping="0.1"/>
  </joint>

  <link name="f1_s2">
    <inertial>
      <origin xyz="0 0 0.02" rpy="0 0 0"/>
      <mass value="0.03"/>
      <inertia ixx="4.6074999999999995e-06" iyy="4.6074999999999995e-06" izz="1.2149999999999998e-06" ixy="0" ixz="0" iyz="0"/>
    </inertial>
    <visual>
      <origin xyz="0 0 0.02" rpy="0 0 0"/>
      <geometry>
        <cylinder radius="0.009" length="0.04"/>
      </geometry>
    </visual>
    <collision>
      <origin xyz="0 0 0.02" rpy="0 0 0"/>
      <geometry>
        <cylinder radius="0.009" length="0.04"/>
      </geometry>
    </collision>
  </link>

  <joint name="j_f1_s1_to_f1_s2" type="revolute">
    <parent link="f1_s1"/>
    <child link="f1_s2"/>
    <origin xyz="0 0 0.05" rpy="0 0 0"/>
    <axis xyz="0 1 0"/>
    <limit 
      lower="-0.7" 
      upper="1.57" 
      effort="10" velocity="1.0"
    />
    <dynamics damping="0.1"/>
  </joint>

  <link name="f1_s3">
    <inertial>
      <origin xyz="0 0 0.015" rpy="0 0 0"/>
      <mass value="0.02"/>
      <inertia ixx="1.8200000000000002e-06" iyy="1.8200000000000002e-06" izz="6.4e-07" ixy="0" ixz="0" iyz="0"/>
    </inertial>
    <visual>
      <origin xyz="0 0 0.015" rpy="0 0 0"/>
      <geometry>
        <cylinder radius="0.008" length="0.03"/>
      </geometry>
    </visual>
    <collision>
      <origin xyz="0 0 0.015" rpy="0 0 0"/>
      <geometry>
        <cylinder radius="0.008" length="0.03"/>
      </geometry>
    </collision>
  </link>

  <joint name="j_f1_s2_to_f1_s3" type="revolute">
    <parent link="f1_s2"/>
    <child link="f1_s3"/>
    <origin xyz="0 0 0.04" rpy="0 0 0"/>
    <axis xyz="0 1 0"/>
    <limit 
      lower="-0.7" 
      upper="1.57" 
      effort="10" velocity="1.0"
    />
    <dynamics damping="0.1"/>
  </joint>


  <link name="f2_s1">
    <inertial>
      <origin xyz="0 0 0.025" rpy="0 0 0"/>
      <mass value="0.05"/>
      <inertia ixx="1.1666666666666668e-05" iyy="1.1666666666666668e-05" izz="2.5e-06" ixy="0" ixz="0" iyz="0"/>
    </inertial>
    <visual>
      <origin xyz="0 0 0.025" rpy="0 0 0"/>
      <geometry>
        <cylinder radius="0.01" length="0.05"/>
      </geometry>
    </visual>
    <collision>
      <origin xyz="0 0 0.025" rpy="0 0 0"/>
      <geometry>
        <cylinder radius="0.01" length="0.05"/>
      </geometry>
    </collision>
  </link>

  <joint name="j_base_to_f2_s1" type="revolute">
    <parent link="base"/>
    <child link="f2_s1"/>
    <origin 
      xyz="3.981633553666317e-05 0.049999984146591736 0.0" 
      rpy="0 0 4.7115"
    />
    <axis xyz="0 1 0"/>
    <limit 
      lower="-0.7" 
      upper="1.57" 
      effort="10" velocity="1.0"
    />
    <dynamics damping="0.1"/>
  </joint>

  <link name="f2_s2">
    <inertial>
      <origin xyz="0 0 0.02" rpy="0 0 0"/>
      <mass value="0.03"/>
      <inertia ixx="4.6074999999999995e-06" iyy="4.6074999999999995e-06" izz="1.2149999999999998e-06" ixy="0" ixz="0" iyz="0"/>
    </inertial>
    <visual>
      <origin xyz="0 0 0.02" rpy="0 0 0"/>
      <geometry>
        <cylinder radius="0.009" length="0.04"/>
      </geometry>
    </visual>
    <collision>
      <origin xyz="0 0 0.02" rpy="0 0 0"/>
      <geometry>
        <cylinder radius="0.009" length="0.04"/>
      </geometry>
    </collision>
  </link>

  <joint name="j_f2_s1_to_f2_s2" type="revolute">
    <parent link="f2_s1"/>
    <child link="f2_s2"/>
    <origin xyz="0 0 0.05" rpy="0 0 0"/>
    <axis xyz="0 1 0"/>
    <limit 
      lower="-0.7" 
      upper="1.57" 
      effort="10" velocity="1.0"
    />
    <dynamics damping="0.1"/>
  </joint>

  <link name="f2_s3">
    <inertial>
      <origin xyz="0 0 0.015" rpy="0 0 0"/>
      <mass value="0.02"/>
      <inertia ixx="1.8200000000000002e-06" iyy="1.8200000000000002e-06" izz="6.4e-07" ixy="0" ixz="0" iyz="0"/>
    </inertial>
    <visual>
      <origin xyz="0 0 0.015" rpy="0 0 0"/>
      <geometry>
        <cylinder radius="0.008" length="0.03"/>
      </geometry>
    </visual>
    <collision>
      <origin xyz="0 0 0.015" rpy="0 0 0"/>
      <geometry>
        <cylinder radius="0.008" length="0.03"/>
      </geometry>
    </collision>
  </link>

  <joint name="j_f2_s2_to_f2_s3" type="revolute">
    <parent link="f2_s2"/>
    <child link="f2_s3"/>
    <origin xyz="0 0 0.04" rpy="0 0 0"/>
    <axis xyz="0 1 0"/>
    <limit 
      lower="-0.7" 
      upper="1.57" 
      effort="10" velocity="1.0"
    />
    <dynamics damping="0.1"/>
  </joint>


  <link name="f3_s1">
    <inertial>
      <origin xyz="0 0 0.025" rpy="0 0 0"/>
      <mass value="0.05"/>
      <inertia ixx="1.1666666666666668e-05" iyy="1.1666666666666668e-05" izz="2.5e-06" ixy="0" ixz="0" iyz="0"/>
    </inertial>
    <visual>
      <origin xyz="0 0 0.025" rpy="0 0 0"/>
      <geometry>
        <cylinder radius="0.01" length="0.05"/>
      </geometry>
    </visual>
    <collision>
      <origin xyz="0 0 0.025" rpy="0 0 0"/>
      <geometry>
        <cylinder radius="0.01" length="0.05"/>
      </geometry>
    </collision>
  </link>

  <joint name="j_base_to_f3_s1" type="revolute">
    <parent link="base"/>
    <child link="f3_s1"/>
    <origin 
      xyz="-0.00011944890561407693 -0.0499998573193859 0.0" 
      rpy="0 0 7.8515"
    />
    <axis xyz="0 1 0"/>
    <limit 
      lower="-0.7" 
      upper="1.57" 
      effort="10" velocity="1.0"
    />
    <dynamics damping="0.1"/>
  </joint>

  <link name="f3_s2">
    <inertial>
      <origin xyz="0 0 0.02" rpy="0 0 0"/>
      <mass value="0.03"/>
      <inertia ixx="4.6074999999999995e-06" iyy="4.6074999999999995e-06" izz="1.2149999999999998e-06" ixy="0" ixz="0" iyz="0"/>
    </inertial>
    <visual>
      <origin xyz="0 0 0.02" rpy="0 0 0"/>
      <geometry>
        <cylinder radius="0.009" length="0.04"/>
      </geometry>
    </visual>
    <collision>
      <origin xyz="0 0 0.02" rpy="0 0 0"/>
      <geometry>
        <cylinder radius="0.009" length="0.04"/>
      </geometry>
    </collision>
  </link>

  <joint name="j_f3_s1_to_f3_s2" type="revolute">
    <parent link="f3_s1"/>
    <child link="f3_s2"/>
    <origin xyz="0 0 0.05" rpy="0 0 0"/>
    <axis xyz="0 1 0"/>
    <limit 
      lower="-0.7" 
      upper="1.57" 
      effort="10" velocity="1.0"
    />
    <dynamics damping="0.1"/>
  </joint>

  <link name="f3_s3">
    <inertial>
      <origin xyz="0 0 0.015" rpy="0 0 0"/>
      <mass value="0.02"/>
      <inertia ixx="1.8200000000000002e-06" iyy="1.8200000000000002e-06" izz="6.4e-07" ixy="0" ixz="0" iyz="0"/>
    </inertial>
    <visual>
      <origin xyz="0 0 0.015" rpy="0 0 0"/>
      <geometry>
        <cylinder radius="0.008" length="0.03"/>
      </geometry>
    </visual>
    <collision>
      <origin xyz="0 0 0.015" rpy="0 0 0"/>
      <geometry>
        <cylinder radius="0.008" length="0.03"/>
      </geometry>
    </collision>
  </link>

  <joint name="j_f3_s2_to_f3_s3" type="revolute">
    <parent link="f3_s2"/>
    <child link="f3_s3"/>
    <origin xyz="0 0 0.04" rpy="0 0 0"/>
    <axis xyz="0 1 0"/>
    <limit 
      lower="-0.7" 
      upper="1.57" 
      effort="10" velocity="1.0"
    />
    <dynamics damping="0.1"/>
  </joint>


  <link name="f4_s1">
    <inertial>
      <origin xyz="0 0 0.025" rpy="0 0 0"/>
      <mass value="0.05"/>
      <inertia ixx="1.1666666666666668e-05" iyy="1.1666666666666668e-05" izz="2.5e-06" ixy="0" ixz="0" iyz="0"/>
    </inertial>
    <visual>
      <origin xyz="0 0 0.025" rpy="0 0 0"/>
      <geometry>
        <cylinder radius="0.01" length="0.05"/>
      </geometry>
    </visual>
    <collision>
      <origin xyz="0 0 0.025" rpy="0 0 0"/>
      <geometry>
        <cylinder radius="0.01" length="0.05"/>
      </geometry>
    </collision>
  </link>

  <joint name="j_base_to_f4_s1" type="revolute">
    <parent link="base"/>
    <child link="f4_s1"/>
    <origin 
      xyz="-0.049999429278357904 0.0002388971295064256 0.0" 
      rpy="0 0 12.5615"
    />
    <axis xyz="0 1 0"/>
    <limit 
      lower="-0.7" 
      upper="1.57" 
      effort="10" velocity="1.0"
    />
    <dynamics damping="0.1"/>
  </joint>

  <link name="f4_s2">
    <inertial>
      <origin xyz="0 0 0.02" rpy="0 0 0"/>
      <mass value="0.03"/>
      <inertia ixx="4.6074999999999995e-06" iyy="4.6074999999999995e-06" izz="1.2149999999999998e-06" ixy="0" ixz="0" iyz="0"/>
    </inertial>
    <visual>
      <origin xyz="0 0 0.02" rpy="0 0 0"/>
      <geometry>
        <cylinder radius="0.009" length="0.04"/>
      </geometry>
    </visual>
    <collision>
      <origin xyz="0 0 0.02" rpy="0 0 0"/>
      <geometry>
        <cylinder radius="0.009" length="0.04"/>
      </geometry>
    </collision>
  </link>

  <joint name="j_f4_s1_to_f4_s2" type="revolute">
    <parent link="f4_s1"/>
    <child link="f4_s2"/>
    <origin xyz="0 0 0.05" rpy="0 0 0"/>
    <axis xyz="0 1 0"/>
    <limit 
      lower="-0.7" 
      upper="1.57" 
      effort="10" velocity="1.0"
    />
    <dynamics damping="0.1"/>
  </joint>

  <link name="f4_s3">
    <inertial>
      <origin xyz="0 0 0.015" rpy="0 0 0"/>
      <mass value="0.02"/>
      <inertia ixx="1.8200000000000002e-06" iyy="1.8200000000000002e-06" izz="6.4e-07" ixy="0" ixz="0" iyz="0"/>
    </inertial>
    <visual>
      <origin xyz="0 0 0.015" rpy="0 0 0"/>
      <geometry>
        <cylinder radius="0.008" length="0.03"/>
      </geometry>
    </visual>
    <collision>
      <origin xyz="0 0 0.015" rpy="0 0 0"/>
      <geometry>
        <cylinder radius="0.008" length="0.03"/>
      </geometry>
    </collision>
  </link>

  <joint name="j_f4_s2_to_f4_s3" type="revolute">
    <parent link="f4_s2"/>
    <child link="f4_s3"/>
    <origin xyz="0 0 0.04" rpy="0 0 0"/>
    <axis xyz="0 1 0"/>
    <limit 
      lower="-0.7" 
      upper="1.57" 
      effort="10" velocity="1.0"
    />
    <dynamics damping="0.1"/>
  </joint>


</robot>